2025-08-30 21:39:57,370 - INFO - 📝 logging to ./bot.log
2025-08-30 21:39:57,370 - INFO - 📝 logging to ./bot.log
2025-08-30 21:39:57,370 - INFO - 🚀 הפעלה (גרסה V5.1.0 / v1.0.32) | interval=60s | DB=./flights.db
2025-08-30 21:39:57,370 - INFO - 🚀 הפעלה (גרסה V5.1.0 / v1.0.32) | interval=60s | DB=./flights.db
2025-08-30 21:39:57,371 - INFO - ✅ DB schema ensured
2025-08-30 21:39:57,371 - INFO - ✅ DB schema ensured
2025-08-30 21:39:57,371 - INFO - ✅ DB schema ensured
2025-08-30 21:39:57,371 - INFO - ✅ DB schema ensured
2025-08-30 21:39:57,371 - INFO - 📁 DB path: /Users/yossimantsour/Desktop/tusbot/tusbot_v2.5.2.3/flights.db
2025-08-30 21:39:57,371 - INFO - 📁 DB path: /Users/yossimantsour/Desktop/tusbot/tusbot_v2.5.2.3/flights.db
2025-08-30 21:39:57,371 - INFO - 🔎 DB attached: {'seq': 0, 'name': 'main', 'file': '/Users/yossimantsour/Desktop/tusbot/tusbot_v2.5.2.3/flights.db'}
2025-08-30 21:39:57,371 - INFO - 🔎 DB attached: {'seq': 0, 'name': 'main', 'file': '/Users/yossimantsour/Desktop/tusbot/tusbot_v2.5.2.3/flights.db'}
2025-08-30 21:39:57,372 - INFO - ✅ DB schema ensured
Traceback (most recent call last):
  File "/Users/yossimantsour/Desktop/tusbot/tusbot_v2.5.2.3/app.py", line 124, in <module>
    .post_init(_startup)
               ^^^^^^^^
NameError: name '_startup' is not defined
